Workbook

Sheet Loans
A1: loan_id | B1: origination_date | C1: original_balance | D1: current_balance | E1: interest_rate | F1: original_term_months | G1: loan_age_months | H1: remaining_term_months | I1: fico_score | J1: ltv_pct | K1: dti_pct | L1: property_state | M1: property_type | N1: occupancy | O1: servicing_fee_rate | P1: delinquency_days | Q1: loan_status | R1: Quality Check | S1: Clean Current Balance | T1: Clean FICO | U1: Include In Valuation | V1: Metric | W1: Value
A2: LN000001 | B2: 45114 | C2: 486400 | D2: 451909.64 | E2: 6.44 | F2: 360 | G2: 26 | H2: 334 | I2: 712 | J2: 72.4 | K2: 37.9 | L2: CA | M2: Single Family | N2: Primary | O2: 0.0025 | P2: 0 | Q2: Current | R2: =IF(D2<0,"ERROR - Negative Balance", IF(I2="", "ERROR - Missing FICO", IF(L2="XX","ERROR - Invalid State", IF(O2<=0,"ERROR - Invalid Servicing Fee",IF(H2 <=0, "ERROR - Invalid Term", "OK"))))) -> OK | S2: =IF(D2<0,"",D2) -> 451909.64 | T2: =IF(I2="","",I2) -> 712 | U2: =IF(R2="OK","YES","NO") -> YES | V2: Total Loan | W2: =COUNTA(A2:A1001) -> 1000
A3: LN000002 | B3: 46048 | C3: 548300 | D3: 380046.3 | E3: 6.214 | F3: 180 | G3: 69 | H3: 111 | I3: 752 | J3: 78.7 | K3: 50.7 | L3: WA | M3: Single Family | N3: Primary | O3: 0.0025 | P3: 0 | Q3: Current | R3: =IF(D3<0,"ERROR - Negative Balance", IF(I3="", "ERROR - Missing FICO", IF(L3="XX","ERROR - Invalid State", IF(O3<=0,"ERROR - Invalid Servicing Fee",IF(H3 <=0, "ERROR - Invalid Term", "OK"))))) -> OK | S3: =IF(D3<0,"",D3) -> 380046.3 | T3: =IF(I3="","",I3) -> 752 | U3: =IF(R3="OK","YES","NO") -> YES | V3: Total Mortage Balance UPB | W3: =SUM(D2:D1001) -> 3.5129186e+08
A4: LN000003 | B4: 43886 | C4: 275200 | D4: 243727.48 | E4: 7.079 | F4: 360 | G4: 42 | H4: 318 | I4: 580 | J4: 79.2 | K4: 21.5 | L4: NC | M4: Townhome | N4: Investment | O4: 0.0025 | P4: 0 | Q4: Current | R4: =IF(D4<0,"ERROR - Negative Balance", IF(I4="", "ERROR - Missing FICO", IF(L4="XX","ERROR - Invalid State", IF(O4<=0,"ERROR - Invalid Servicing Fee",IF(H4 <=0, "ERROR - Invalid Term", "OK"))))) -> OK | S4: =IF(D4<0,"",D4) -> 243727.48 | T4: =IF(I4="","",I4) -> 580 | U4: =IF(R4="OK","YES","NO") -> YES | V4: Avg. Mortage Interest Rate | W4: =AVERAGE(E2:E1001) -> 6.248606
A5: LN000004 | B5: 45959 | C5: 462400 | D5: 422332.15 | E5: 6.764 | F5: 360 | G5: 32 | H5: 328 | I5: 701 | J5: 75 | K5: 35.8 | L5: GA | M5: Condo | N5: Primary | O5: 0.0025 | P5: 30 | Q5: 30 DPD | R5: =IF(D5<0,"ERROR - Negative Balance", IF(I5="", "ERROR - Missing FICO", IF(L5="XX","ERROR - Invalid State", IF(O5<=0,"ERROR - Invalid Servicing Fee",IF(H5 <=0, "ERROR - Invalid Term", "OK"))))) -> OK | S5: =IF(D5<0,"",D5) -> 422332.15 | T5: =IF(I5="","",I5) -> 701 | U5: =IF(R5="OK","YES","NO") -> YES | V5: Avg. FICO Score | W5: =AVERAGE(I2:I1001) -> 726.15516
A6: LN000005 | B6: 44344 | C6: 435900 | D6: 303414.81 | E6: 6.763 | F6: 180 | G6: 60 | H6: 120 | I6: 700 | J6: 88.5 | K6: 34.3 | L6: TX | M6: Townhome | N6: Primary | O6: 0.0025 | P6: 0 | Q6: Current | R6: =IF(D6<0,"ERROR - Negative Balance", IF(I6="", "ERROR - Missing FICO", IF(L6="XX","ERROR - Invalid State", IF(O6<=0,"ERROR - Invalid Servicing Fee",IF(H6 <=0, "ERROR - Invalid Term", "OK"))))) -> OK | S6: =IF(D6<0,"",D6) -> 303414.81 | T6: =IF(I6="","",I6) -> 700 | U6: =IF(R6="OK","YES","NO") -> YES | V6: Avg. Loan-to-Value ratio LTI | W6: =AVERAGE(J2:J1001) -> 75.944444
A7: LN000006 | B7: 43601 | C7: 566400 | D7: 458369.93 | E7: 6.421 | F7: 180 | G7: 34 | H7: 146 | I7: 807 | J7: 74.3 | K7: 31.3 | L7: TX | M7: Condo | N7: Primary | O7: 0.00275 | P7: 0 | Q7: Current | R7: =IF(D7<0,"ERROR - Negative Balance", IF(I7="", "ERROR - Missing FICO", IF(L7="XX","ERROR - Invalid State", IF(O7<=0,"ERROR - Invalid Servicing Fee",IF(H7 <=0, "ERROR - Invalid Term", "OK"))))) -> OK | S7: =IF(D7<0,"",D7) -> 458369.93 | T7: =IF(I7="","",I7) -> 807 | U7: =IF(R7="OK","YES","NO") -> YES | V7: Avg. Debt-to-Income ratio DTI | W7: =AVERAGE(K2:K1001) -> 34.8817
A8: LN000007 | B8: 44790 | C8: 603000 | D8: 569933.7 | E8: 5.625 | F8: 360 | G8: 25 | H8: 335 | I8: 747 | J8: 70.5 | K8: 34.4 | L8: CO | M8: Condo | N8: Primary | O8: 0.0025 | P8: 0 | Q8: Current | R8: =IF(D8<0,"ERROR - Negative Balance", IF(I8="", "ERROR - Missing FICO", IF(L8="XX","ERROR - Invalid State", IF(O8<=0,"ERROR - Invalid Servicing Fee",IF(H8 <=0, "ERROR - Invalid Term", "OK"))))) -> OK | S8: =IF(D8<0,"",D8) -> 569933.7 | T8: =IF(I8="","",I8) -> 747 | U8: =IF(R8="OK","YES","NO") -> YES
A9: LN000008 | B9: 45098 | C9: 156100 | D9: 144019.89 | E9: 6.461 | F9: 360 | G9: 30 | H9: 330 | I9: 752 | J9: 47.5 | K9: 30.7 | L9: TN | M9: Townhome | N9: Primary | O9: 0.0025 | P9: 0 | Q9: Current | R9: =IF(D9<0,"ERROR - Negative Balance", IF(I9="", "ERROR - Missing FICO", IF(L9="XX","ERROR - Invalid State", IF(O9<=0,"ERROR - Invalid Servicing Fee",IF(H9 <=0, "ERROR - Invalid Term", "OK"))))) -> OK | S9: =IF(D9<0,"",D9) -> 144019.89 | T9: =IF(I9="","",I9) -> 752 | U9: =IF(R9="OK","YES","NO") -> YES
A10: LN000009 | B10: 43498 | C10: 487000 | D10: 405607.96 | E10: 6.292 | F10: 360 | G10: 68 | H10: 292 | I10: 749 | J10: 67.2 | K10: 44.9 | L10: GA | M10: Single Family | N10: Primary | O10: 0.0025 | P10: 0 | Q10: Current | R10: =IF(D10<0,"ERROR - Negative Balance", IF(I10="", "ERROR - Missing FICO", IF(L10="XX","ERROR - Invalid State", IF(O10<=0,"ERROR - Invalid Servicing Fee",IF(H10 <=0, "ERROR - Invalid Term", "OK"))))) -> OK | S10: =IF(D10<0,"",D10) -> 405607.96 | T10: =IF(I10="","",I10) -> 749 | U10: =IF(R10="OK","YES","NO") -> YES | V10: No. of Loans with ERROR | W10: =COUNTIF(R2:R1001,"ERROR*") -> 5
A11: LN000010 | B11: 45256 | C11: 175900 | D11: 158337.27 | E11: 5.51 | F11: 360 | G11: 41 | H11: 319 | I11: 727 | J11: 61.5 | K11: 45.7 | L11: NC | M11: Single Family | N11: Primary | O11: 0.0025 | P11: 0 | Q11: Current | R11: =IF(D11<0,"ERROR - Negative Balance", IF(I11="", "ERROR - Missing FICO", IF(L11="XX","ERROR - Invalid State", IF(O11<=0,"ERROR - Invalid Servicing Fee",IF(H11 <=0, "ERROR - Invalid Term", "OK"))))) -> OK | S11: =IF(D11<0,"",D11) -> 158337.27 | T11: =IF(I11="","",I11) -> 727 | U11: =IF(R11="OK","YES","NO") -> YES | V11: No. of Loans with OK Status | W11: =COUNTIF(R2:R1001,"OK") -> 995
A12: LN000011 | B12: 43743 | C12: 424400 | D12: 417585.58 | E12: 7.036 | F12: 360 | G12: 7 | H12: 353 | I12: 809 | J12: 75.6 | K12: 35.7 | L12: CO | M12: Single Family | N12: Primary | O12: 0.0025 | P12: 0 | Q12: Current | R12: =IF(D12<0,"ERROR - Negative Balance", IF(I12="", "ERROR - Missing FICO", IF(L12="XX","ERROR - Invalid State", IF(O12<=0,"ERROR - Invalid Servicing Fee",IF(H12 <=0, "ERROR - Invalid Term", "OK"))))) -> OK | S12: =IF(D12<0,"",D12) -> 417585.58 | T12: =IF(I12="","",I12) -> 809 | U12: =IF(R12="OK","YES","NO") -> YES
A13: LN000012 | B13: 45646 | C13: 293800 | D13: 274812.8 | E13: 6.966 | F13: 360 | G13: 27 | H13: 333 | I13: 598 | J13: 62.2 | K13: 33.9 | L13: WA | M13: 2-4 Unit | N13: Primary | O13: 0.0025 | P13: 0 | Q13: Current | R13: =IF(D13<0,"ERROR - Negative Balance", IF(I13="", "ERROR - Missing FICO", IF(L13="XX","ERROR - Invalid State", IF(O13<=0,"ERROR - Invalid Servicing Fee",IF(H13 <=0, "ERROR - Invalid Term", "OK"))))) -> OK | S13: =IF(D13<0,"",D13) -> 274812.8 | T13: =IF(I13="","",I13) -> 598 | U13: =IF(R13="OK","YES","NO") -> YES | V13: ERROR percentage | W13: =COUNTIF(R2:R1001,"ERROR*")/COUNTA(A2:A1001) -> 0.005
A14: LN000013 | B14: 44215 | C14: 303400 | D14: 289552.02 | E14: 5.506 | F14: 360 | G14: 21 | H14: 339 | I14: 733 | J14: 82.7 | K14: 31.1 | L14: VA | M14: Townhome | N14: Investment | O14: 0.0025 | P14: 0 | Q14: Current | R14: =IF(D14<0,"ERROR - Negative Balance", IF(I14="", "ERROR - Missing FICO", IF(L14="XX","ERROR - Invalid State", IF(O14<=0,"ERROR - Invalid Servicing Fee",IF(H14 <=0, "ERROR - Invalid Term", "OK"))))) -> OK | S14: =IF(D14<0,"",D14) -> 289552.02 | T14: =IF(I14="","",I14) -> 733 | U14: =IF(R14="OK","YES","NO") -> YES
A15: LN000014 | B15: 45639 | C15: 326500 | D15: 300671.08 | E15: 5.835 | F15: 240 | G15: 23 | H15: 217 | I15: 787 | J15: 88.2 | K15: 35.7 | L15: TX | M15: Single Family | N15: Primary | O15: 0.0025 | P15: 0 | Q15: Current | R15: =IF(D15<0,"ERROR - Negative Balance", IF(I15="", "ERROR - Missing FICO", IF(L15="XX","ERROR - Invalid State", IF(O15<=0,"ERROR - Invalid Servicing Fee",IF(H15 <=0, "ERROR - Invalid Term", "OK"))))) -> OK | S15: =IF(D15<0,"",D15) -> 300671.08 | T15: =IF(I15="","",I15) -> 787 | U15: =IF(R15="OK","YES","NO") -> YES
A16: LN000015 | B16: 45858 | C16: 460600 | D16: 397825.62 | E16: 5.893 | F16: 360 | G16: 59 | H16: 301 | I16: 621 | J16: 75.7 | K16: 49.8 | L16: TX | M16: Condo | N16: Primary | O16: 0.0025 | P16: 0 | Q16: Current | R16: =IF(D16<0,"ERROR - Negative Balance", IF(I16="", "ERROR - Missing FICO", IF(L16="XX","ERROR - Invalid State", IF(O16<=0,"ERROR - Invalid Servicing Fee",IF(H16 <=0, "ERROR - Invalid Term", "OK"))))) -> OK | S16: =IF(D16<0,"",D16) -> 397825.62 | T16: =IF(I16="","",I16) -> 621 | U16: =IF(R16="OK","YES","NO") -> YES | V16: After excluding loans that failed 5 quality check
A17: LN000016 | B17: 43482 | C17: 317000 | D17: 287222.24 | E17: 6.646 | F17: 360 | G17: 35 | H17: 325 | I17: 771 | J17: 65.2 | K17: 34.2 | L17: TX | M17: Townhome | N17: Primary | O17: 0.0025 | P17: 0 | Q17: Current | R17: =IF(D17<0,"ERROR - Negative Balance", IF(I17="", "ERROR - Missing FICO", IF(L17="XX","ERROR - Invalid State", IF(O17<=0,"ERROR - Invalid Servicing Fee",IF(H17 <=0, "ERROR - Invalid Term", "OK"))))) -> OK | S17: =IF(D17<0,"",D17) -> 287222.24 | T17: =IF(I17="","",I17) -> 771 | U17: =IF(R17="OK","YES","NO") -> YES | V17: Total Portfolio UPB | W17: =SUMIF(U2:U1001,"YES",S2:S1001) -> 3.4948127e+08
A18: LN000017 | B18: 44867 | C18: 516300 | D18: 406648.62 | E18: 6.572 | F18: 180 | G18: 50 | H18: 130 | I18: 683 | J18: 79.2 | K18: 28.3 | L18: CA | M18: Single Family | N18: Primary | O18: 0.0025 | P18: 90 | Q18: 90 DPD | R18: =IF(D18<0,"ERROR - Negative Balance", IF(I18="", "ERROR - Missing FICO", IF(L18="XX","ERROR - Invalid State", IF(O18<=0,"ERROR - Invalid Servicing Fee",IF(H18 <=0, "ERROR - Invalid Term", "OK"))))) -> OK | S18: =IF(D18<0,"",D18) -> 406648.62 | T18: =IF(I18="","",I18) -> 683 | U18: =IF(R18="OK","YES","NO") -> YES
A19: LN000018 | B19: 44283 | C19: 352300 | D19: 330096.7 | E19: 6.279 | F19: 360 | G19: 24 | H19: 336 | J19: 96.8 | K19: 31.8 | L19: AZ | M19: Single Family | N19: Investment | O19: 0.0025 | P19: 0 | Q19: Current | R19: =IF(D19<0,"ERROR - Negative Balance", IF(I19="", "ERROR - Missing FICO", IF(L19="XX","ERROR - Invalid State", IF(O19<=0,"ERROR - Invalid Servicing Fee",IF(H19 <=0, "ERROR - Invalid Term", "OK"))))) -> ERROR - Missing FICO | S19: =IF(D19<0,"",D19) -> 330096.7 | T19: =IF(I19="","",I19) | U19: =IF(R19="OK","YES","NO") -> NO
A20: LN000019 | B20: 45573 | C20: 184200 | D20: 159762.42 | E20: 6.428 | F20: 240 | G20: 39 | H20: 201 | I20: 682 | J20: 93.4 | K20: 41 | L20: FL | M20: Townhome | N20: Primary | O20: 0.0025 | P20: 0 | Q20: Current | R20: =IF(D20<0,"ERROR - Negative Balance", IF(I20="", "ERROR - Missing FICO", IF(L20="XX","ERROR - Invalid State", IF(O20<=0,"ERROR - Invalid Servicing Fee",IF(H20 <=0, "ERROR - Invalid Term", "OK"))))) -> OK | S20: =IF(D20<0,"",D20) -> 159762.42 | T20: =IF(I20="","",I20) -> 682 | U20: =IF(R20="OK","YES","NO") -> YES
A21: LN000020 | B21: 45126 | C21: 541900 | D21: 520913.34 | E21: 5.413 | F21: 360 | G21: 18 | H21: 342 | I21: 778 | J21: 60.5 | K21: 29.3 | L21: CA | M21: Single Family | N21: Primary | O21: 0.0025 | P21: 0 | Q21: Current | R21: =IF(D21<0,"ERROR - Negative Balance", IF(I21="", "ERROR - Missing FICO", IF(L21="XX","ERROR - Invalid State", IF(O21<=0,"ERROR - Invalid Servicing Fee",IF(H21 <=0, "ERROR - Invalid Term", "OK"))))) -> OK | S21: =IF(D21<0,"",D21) -> 520913.34 | T21: =IF(I21="","",I21) -> 778 | U21: =IF(R21="OK","YES","NO") -> YES
A22: LN000021 | B22: 43932 | C22: 292900 | D22: 260085.76 | E22: 6.498 | F22: 360 | G22: 48 | H22: 312 | I22: 709 | J22: 60.1 | K22: 34.7 | L22: GA | M22: Condo | N22: Investment | O22: 0.0025 | P22: 0 | Q22: Current | R22: =IF(D22<0,"ERROR - Negative Balance", IF(I22="", "ERROR - Missing FICO", IF(L22="XX","ERROR - Invalid State", IF(O22<=0,"ERROR - Invalid Servicing Fee",IF(H22 <=0, "ERROR - Invalid Term", "OK"))))) -> OK | S22: =IF(D22<0,"",D22) -> 260085.76 | T22: =IF(I22="","",I22) -> 709 | U22: =IF(R22="OK","YES","NO") -> YES
A23: LN000022 | B23: 44093 | C23: 366400 | D23: 310664.55 | E23: 6.184 | F23: 360 | G23: 67 | H23: 293 | I23: 772 | J23: 57.3 | K23: 38.8 | L23: TX | M23: Single Family | N23: Primary | O23: 0.0025 | P23: 0 | Q23: Current | R23: =IF(D23<0,"ERROR - Negative Balance", IF(I23="", "ERROR - Missing FICO", IF(L23="XX","ERROR - Invalid State", IF(O23<=0,"ERROR - Invalid Servicing Fee",IF(H23 <=0, "ERROR - Invalid Term", "OK"))))) -> OK | S23: =IF(D23<0,"",D23) -> 310664.55 | T23: =IF(I23="","",I23) -> 772 | U23: =IF(R23="OK","YES","NO") -> YES
A24: LN000023 | B24: 45904 | C24: 492700 | D24: 458865.93 | E24: 5.809 | F24: 360 | G24: 27 | H24: 333 | I24: 749 | J24: 63.5 | K24: 29.9 | L24: CA | M24: Townhome | N24: Investment | O24: 0.003 | P24: 0 | Q24: Current | R24: =IF(D24<0,"ERROR - Negative Balance", IF(I24="", "ERROR - Missing FICO", IF(L24="XX","ERROR - Invalid State", IF(O24<=0,"ERROR - Invalid Servicing Fee",IF(H24 <=0, "ERROR - Invalid Term", "OK"))))) -> OK | S24: =IF(D24<0,"",D24) -> 458865.93 | T24: =IF(I24="","",I24) -> 749 | U24: =IF(R24="OK","YES","NO") -> YES
A25: LN000024 | B25: 44676 | C25: 316200 | D25: 273283.64 | E25: 5.254 | F25: 360 | G25: 57 | H25: 303 | I25: 681 | J25: 78.8 | K25: 20.9 | L25: CA | M25: 2-4 Unit | N25: Primary | O25: 0.0025 | P25: 0 | Q25: Current | R25: =IF(D25<0,"ERROR - Negative Balance", IF(I25="", "ERROR - Missing FICO", IF(L25="XX","ERROR - Invalid State", IF(O25<=0,"ERROR - Invalid Servicing Fee",IF(H25 <=0, "ERROR - Invalid Term", "OK"))))) -> OK | S25: =IF(D25<0,"",D25) -> 273283.64 | T25: =IF(I25="","",I25) -> 681 | U25: =IF(R25="OK","YES","NO") -> YES
A26: LN000025 | B26: 46011 | C26: 178300 | D26: 148945.63 | E26: 6.268 | F26: 360 | G26: 57 | H26: 303 | I26: 753 | J26: 69.9 | K26: 26.4 | L26: FL | M26: Townhome | N26: Primary | O26: 0.0025 | P26: 0 | Q26: Current | R26: =IF(D26<0,"ERROR - Negative Balance", IF(I26="", "ERROR - Missing FICO", IF(L26="XX","ERROR - Invalid State", IF(O26<=0,"ERROR - Invalid Servicing Fee",IF(H26 <=0, "ERROR - Invalid Term", "OK"))))) -> OK | S26: =IF(D26<0,"",D26) -> 148945.63 | T26: =IF(I26="","",I26) -> 753 | U26: =IF(R26="OK","YES","NO") -> YES
A27: LN000026 | B27: 44065 | C27: 337000 | D27: 297120.11 | E27: 6.482 | F27: 360 | G27: 41 | H27: 319 | I27: 689 | J27: 66.8 | K27: 28.1 | L27: VA | M27: Single Family | N27: Primary | O27: 0.0025 | P27: 30 | Q27: 30 DPD | R27: =IF(D27<0,"ERROR - Negative Balance", IF(I27="", "ERROR - Missing FICO", IF(L27="XX","ERROR - Invalid State", IF(O27<=0,"ERROR - Invalid Servicing Fee",IF(H27 <=0, "ERROR - Invalid Term", "OK"))))) -> OK | S27: =IF(D27<0,"",D27) -> 297120.11 | T27: =IF(I27="","",I27) -> 689 | U27: =IF(R27="OK","YES","NO") -> YES
A28: LN000027 | B28: 45204 | C28: 622200 | D28: 585568.41 | E28: 5.143 | F28: 360 | G28: 24 | H28: 336 | I28: 729 | J28: 87.4 | K28: 33.2 | L28: TX | M28: Townhome | N28: Primary | O28: 0.0025 | P28: 0 | Q28: Current | R28: =IF(D28<0,"ERROR - Negative Balance", IF(I28="", "ERROR - Missing FICO", IF(L28="XX","ERROR - Invalid State", IF(O28<=0,"ERROR - Invalid Servicing Fee",IF(H28 <=0, "ERROR - Invalid Term", "OK"))))) -> OK | S28: =IF(D28<0,"",D28) -> 585568.41 | T28: =IF(I28="","",I28) -> 729 | U28: =IF(R28="OK","YES","NO") -> YES
A29: LN000028 | B29: 44850 | C29: 470900 | D29: 415298.97 | E29: 6.262 | F29: 360 | G29: 43 | H29: 317 | I29: 708 | J29: 81.8 | K29: 35.4 | L29: AZ | M29: Townhome | N29: Investment | O29: 0.003 | P29: 0 | Q29: Current | R29: =IF(D29<0,"ERROR - Negative Balance", IF(I29="", "ERROR - Missing FICO", IF(L29="XX","ERROR - Invalid State", IF(O29<=0,"ERROR - Invalid Servicing Fee",IF(H29 <=0, "ERROR - Invalid Term", "OK"))))) -> OK | S29: =IF(D29<0,"",D29) -> 415298.97 | T29: =IF(I29="","",I29) -> 708 | U29: =IF(R29="OK","YES","NO") -> YES
A30: LN000029 | B30: 45312 | C30: 485700 | D30: 422630.78 | E30: 6.329 | F30: 360 | G30: 62 | H30: 298 | I30: 774 | J30: 57.2 | K30: 41.6 | L30: GA | M30: Single Family | N30: Primary | O30: 0.0025 | P30: 90 | Q30: 90 DPD | R30: =IF(D30<0,"ERROR - Negative Balance", IF(I30="", "ERROR - Missing FICO", IF(L30="XX","ERROR - Invalid State", IF(O30<=0,"ERROR - Invalid Servicing Fee",IF(H30 <=0, "ERROR - Invalid Term", "OK"))))) -> OK | S30: =IF(D30<0,"",D30) -> 422630.78 | T30: =IF(I30="","",I30) -> 774 | U30: =IF(R30="OK","YES","NO") -> YES
A31: LN000030 | B31: 45321 | C31: 466100 | D31: 436504.48 | E31: 5.89 | F31: 360 | G31: 25 | H31: 335 | I31: 755 | J31: 86.8 | K31: 25.2 | L31: CO | M31: Townhome | N31: Primary | O31: 0.0025 | P31: 0 | Q31: Current | R31: =IF(D31<0,"ERROR - Negative Balance", IF(I31="", "ERROR - Missing FICO", IF(L31="XX","ERROR - Invalid State", IF(O31<=0,"ERROR - Invalid Servicing Fee",IF(H31 <=0, "ERROR - Invalid Term", "OK"))))) -> OK | S31: =IF(D31<0,"",D31) -> 436504.48 | T31: =IF(I31="","",I31) -> 755 | U31: =IF(R31="OK","YES","NO") -> YES
... A43: LN000042 | B43: 45138 | C43: 635300 | D43: 553960.07 | E43: 7.109 | F43: 360 | G43: 47 | H43: 313 | I43: 793 | J43: 86.4 | K43: 25 | L43: FL | M43: Townhome | N43: Primary | O43: 0.0025 | P43: 0 | Q43: Current | R43: =IF(D43<0,"ERROR - Negative Balance", IF(I43="", "ERROR - Missing FICO", IF(L43="XX","ERROR - Invalid State", IF(O43<=0,"ERROR - Invalid Servicing Fee",IF(H43 <=0, "ERROR - Invalid Term", "OK"))))) -> OK | S43: =IF(D43<0,"",D43) -> 553960.07 | T43: =IF(I43="","",I43) -> 793 | U43: =IF(R43="OK","YES","NO") -> YES
A44: LN000043 | B44: 44844 | C44: 206700 | D44: 199010.63 | E44: 6.017 | F44: 360 | G44: 14 | H44: 346 | I44: 789 | K44: 40.8 | L44: CO | M44: Single Family | N44: Primary | O44: 0.0025 | P44: 0 | Q44: Current | R44: =IF(D44<0,"ERROR - Negative Balance", IF(I44="", "ERROR - Missing FICO", IF(L44="XX","ERROR - Invalid State", IF(O44<=0,"ERROR - Invalid Servicing Fee",IF(H44 <=0, "ERROR - Invalid Term", "OK"))))) -> OK | S44: =IF(D44<0,"",D44) -> 199010.63 | T44: =IF(I44="","",I44) -> 789 | U44: =IF(R44="OK","YES","NO") -> YES
A45: LN000044 | B45: 45405 | C45: 351800 | D45: 340395.84 | E45: 6.542 | F45: 360 | G45: 12 | H45: 348 | I45: 680 | J45: 66.9 | K45: 47.3 | L45: TN | M45: Condo | N45: Primary | O45: 0.0025 | P45: 0 | Q45: Current | R45: =IF(D45<0,"ERROR - Negative Balance", IF(I45="", "ERROR - Missing FICO", IF(L45="XX","ERROR - Invalid State", IF(O45<=0,"ERROR - Invalid Servicing Fee",IF(H45 <=0, "ERROR - Invalid Term", "OK"))))) -> OK | S45: =IF(D45<0,"",D45) -> 340395.84 | T45: =IF(I45="","",I45) -> 680 | U45: =IF(R45="OK","YES","NO") -> YES
A46: LN000045 | B46: 44123 | C46: 518900 | D46: 485332.69 | E46: 5.761 | F46: 360 | G46: 24 | H46: 336 | I46: 616 | J46: 64.9 | K46: 38.3 | L46: TX | M46: Townhome | N46: Investment | O46: 0.00275 | P46: 90 | Q46: 90 DPD | R46: =IF(D46<0,"ERROR - Negative Balance", IF(I46="", "ERROR - Missing FICO", IF(L46="XX","ERROR - Invalid State", IF(O46<=0,"ERROR - Invalid Servicing Fee",IF(H46 <=0, "ERROR - Invalid Term", "OK"))))) -> OK | S46: =IF(D46<0,"",D46) -> 485332.69 | T46: =IF(I46="","",I46) -> 616 | U46: =IF(R46="OK","YES","NO") -> YES
A47: LN000046 | B47: 44519 | C47: 502300 | D47: 457536.15 | E47: 6.377 | F47: 360 | G47: 36 | H47: 324 | I47: 620 | J47: 69.1 | K47: 31 | L47: GA | M47: Single Family | N47: Primary | O47: 0.0025 | P47: 0 | Q47: Current | R47: =IF(D47<0,"ERROR - Negative Balance", IF(I47="", "ERROR - Missing FICO", IF(L47="XX","ERROR - Invalid State", IF(O47<=0,"ERROR - Invalid Servicing Fee",IF(H47 <=0, "ERROR - Invalid Term", "OK"))))) -> OK | S47: =IF(D47<0,"",D47) -> 457536.15 | T47: =IF(I47="","",I47) -> 620 | U47: =IF(R47="OK","YES","NO") -> YES
A48: LN000047 | B48: 44042 | C48: 361400 | D48: 328736.67 | E48: 7.069 | F48: 360 | G48: 40 | H48: 320 | I48: 681 | J48: 75.2 | K48: 28.2 | L48: CA | M48: Single Family | N48: Primary | O48: 0.0025 | P48: 0 | Q48: Current | R48: =IF(D48<0,"ERROR - Negative Balance", IF(I48="", "ERROR - Missing FICO", IF(L48="XX","ERROR - Invalid State", IF(O48<=0,"ERROR - Invalid Servicing Fee",IF(H48 <=0, "ERROR - Invalid Term", "OK"))))) -> OK | S48: =IF(D48<0,"",D48) -> 328736.67 | T48: =IF(I48="","",I48) -> 681 | U48: =IF(R48="OK","YES","NO") -> YES
A49: LN000048 | B49: 44188 | C49: 323300 | D49: 272576.66 | E49: 6.696 | F49: 360 | G49: 62 | H49: 298 | I49: 820 | J49: 82.6 | K49: 32.5 | L49: AZ | M49: Single Family | N49: Primary | O49: 0.00275 | P49: 0 | Q49: Current | R49: =IF(D49<0,"ERROR - Negative Balance", IF(I49="", "ERROR - Missing FICO", IF(L49="XX","ERROR - Invalid State", IF(O49<=0,"ERROR - Invalid Servicing Fee",IF(H49 <=0, "ERROR - Invalid Term", "OK"))))) -> OK | S49: =IF(D49<0,"",D49) -> 272576.66 | T49: =IF(I49="","",I49) -> 820 | U49: =IF(R49="OK","YES","NO") -> YES
A50: LN000049 | B50: 45735 | C50: 348800 | D50: 282462.07 | E50: 5.229 | F50: 360 | G50: 66 | H50: 294 | I50: 702 | J50: 70.8 | K50: 44.7 | L50: AZ | M50: Townhome | N50: Primary | O50: 0.0025 | P50: 0 | Q50: Current | R50: =IF(D50<0,"ERROR - Negative Balance", IF(I50="", "ERROR - Missing FICO", IF(L50="XX","ERROR - Invalid State", IF(O50<=0,"ERROR - Invalid Servicing Fee",IF(H50 <=0, "ERROR - Invalid Term", "OK"))))) -> OK | S50: =IF(D50<0,"",D50) -> 282462.07 | T50: =IF(I50="","",I50) -> 702 | U50: =IF(R50="OK","YES","NO") -> YES
A51: LN000050 | B51: 45107 | C51: 282100 | D51: 242892.71 | E51: 6.621 | F51: 240 | G51: 36 | H51: 204 | I51: 733 | J51: 70.4 | K51: 32.3 | L51: TX | M51: Single Family | N51: Primary | O51: 0.0025 | P51: 0 | Q51: Current | R51: =IF(D51<0,"ERROR - Negative Balance", IF(I51="", "ERROR - Missing FICO", IF(L51="XX","ERROR - Invalid State", IF(O51<=0,"ERROR - Invalid Servicing Fee",IF(H51 <=0, "ERROR - Invalid Term", "OK"))))) -> OK | S51: =IF(D51<0,"",D51) -> 242892.71 | T51: =IF(I51="","",I51) -> 733 | U51: =IF(R51="OK","YES","NO") -> YES
...

Sheet Monthly_Performance
A1: loan_id | B1: month_end | C1: beginning_upb | D1: scheduled_interest | E1: scheduled_principal | F1: prepayment_amount | G1: default_amount | H1: ending_upb | I1: servicing_revenue | J1: servicing_cost | K1: net_servicing_cash_flow
A2: LN000001 | B2: 46053 | C2: 451909.64 | D2: 2425.25 | E2: 487.43 | F2: 2831.63 | G2: 634.83 | H2: 447955.75 | I2: 93.74 | J2: 5.28 | K2: 88.45
A3: LN000001 | B3: 46081 | C3: 447955.75 | D3: 2404.03 | E3: 483.17 | F3: 2806.85 | G3: 629.28 | H3: 444036.45 | I3: 92.92 | J3: 5.28 | K3: 87.63
A4: LN000001 | B4: 46112 | C4: 444036.45 | D4: 2383 | E4: 478.94 | F4: 2782.29 | G4: 623.77 | H4: 440151.44 | I4: 92.1 | J4: 5.28 | K4: 86.82
A5: LN000001 | B5: 46142 | C5: 440151.44 | D5: 2362.15 | E5: 474.75 | F5: 2757.95 | G5: 618.32 | H5: 436300.42 | I5: 91.3 | J5: 5.28 | K5: 86.01
A6: LN000001 | B6: 46173 | C6: 436300.42 | D6: 2341.48 | E6: 470.6 | F6: 2733.82 | G6: 612.91 | H6: 432483.1 | I6: 90.5 | J6: 5.28 | K6: 85.21
A7: LN000001 | B7: 46203 | C7: 432483.1 | D7: 2320.99 | E7: 466.48 | F7: 2709.9 | G7: 607.54 | H7: 428699.17 | I7: 89.71 | J7: 5.28 | K7: 84.42
A8: LN000001 | B8: 46234 | C8: 428699.17 | D8: 2300.69 | E8: 462.4 | F8: 2686.19 | G8: 602.23 | H8: 424948.36 | I8: 88.92 | J8: 5.28 | K8: 83.64
A9: LN000001 | B9: 46265 | C9: 424948.36 | D9: 2280.56 | E9: 458.35 | F9: 2662.69 | G9: 596.96 | H9: 421230.36 | I9: 88.14 | J9: 5.28 | K9: 82.86
A10: LN000001 | B10: 46295 | C10: 421230.36 | D10: 2260.6 | E10: 454.34 | F10: 2639.39 | G10: 591.74 | H10: 417544.88 | I10: 87.37 | J10: 5.28 | K10: 82.09
A11: LN000001 | B11: 46326 | C11: 417544.88 | D11: 2240.82 | E11: 450.37 | F11: 2616.3 | G11: 586.56 | H11: 413891.66 | I11: 86.61 | J11: 5.28 | K11: 81.32
A12: LN000001 | B12: 46356 | C12: 413891.66 | D12: 2221.22 | E12: 446.43 | F12: 2593.41 | G12: 581.43 | H12: 410270.4 | I12: 85.85 | J12: 5.28 | K12: 80.57
A13: LN000001 | B13: 46387 | C13: 410270.4 | D13: 2201.78 | E13: 442.52 | F13: 2570.72 | G13: 576.34 | H13: 406680.82 | I13: 85.1 | J13: 5.28 | K13: 79.81
... A12001: LN001000 | B12001: 46387 | C12001: 178529.04 | D12001: 1060.76 | E12001: 202.54 | F12001: 1241.26 | G12001: 101.82 | H12001: 176983.42 | I12001: 40.74 | J12001: 6 | K12001: 34.73

Sheet Assumptions
A1: assumption | B1: value | C1: description
A2: Base CPR | B2: 0.1 | C2: Annual conditional prepayment rate | D2: Single Monthly Mortality(SMM) | E2: =1-(1-B2)^(1/12) -> 0.008741611
A3: Base Annual Default Rate | B3: 0.02 | C3: Annual expected default rate
A4: Base Discount Rate | B4: 0.08 | C4: Annual discount rate applied to projected MSR cash flows
A5: Base Annual Servicing Cost | B5: 60 | C5: Base annual servicing expense per loan
A6: Base Ancillary Revenue per Loan per Month | B6: 2 | C6: Illustrative ancillary servicing revenue
A7: Upside CPR | B7: 0.06 | C7: Lower prepayment / upside case
A8: Upside Default Rate | B8: 0.01 | C8: Lower default / upside case
A9: Upside Discount Rate | B9: 0.07 | C9: Lower discount rate / upside case
A10: Stress CPR | B10: 0.15 | C10: Higher prepayment / stress case
A11: Stress Default Rate | B11: 0.04 | C11: Higher default / stress case
A12: Stress Discount Rate | B12: 0.1 | C12: Higher discount rate / stress case

Sheet Data_Dictionary
A1: field | B1: definition
A2: loan_id | B2: Unique mortgage identifier
A3: current_balance | B3: Current unpaid principal balance (UPB)
A4: interest_rate | B4: Annual note interest rate
A5: remaining_term_months | B5: Number of months remaining on the mortgage
A6: fico_score | B6: Borrower credit score
A7: ltv_pct | B7: Loan-to-value ratio in percent
A8: dti_pct | B8: Debt-to-income ratio in percent
A9: servicing_fee_rate | B9: Annual servicing fee paid to the servicer
A10: delinquency_days | B10: Days past due
A11: prepayment_amount | B11: Expected principal paid off early during the month
A12: default_amount | B12: Expected principal balance lost to default during the month
... A15: net_servicing_cash_flow | B15: Servicing revenue minus servicing expense

Sheet Portfolio_Summary
A1: metric | B1: value
A2: Loan Count | B2: 1000
A3: Total Current UPB | B3: 3.5141686e+08
A4: Average Interest Rate | B4: 6.248606
A5: Average FICO | B5: 726.15516
A6: Average LTV | B6: 75.944444
A7: Average DTI | B7: 34.8817
A8: Delinquent Loan Count | B8: 92
A9: Delinquent UPB | B9: 33987838
A10: Weighted Average Servicing Fee | B10: 0.002581151

Sheet Sheet1
A2: Missing FICO Score | B2: LN000018
A3: Mortgage with -ve balance | B3: LN000088
A4: Invalid State XX | B4: LN000157
A5: Servicing Fee 0.00 | B5: LN000245
A6: Remaining Term 0 month | B6: LN000392

Sheet RoughBook
B1: Month 1 | D1: Month 2
A2: LN000001 | B2: 451909.64 | D2: 447476.05
A4: Step- 1
A5: Calculate SMM | B5: 1-(1-CPR)^1/12
B6: =1-(1-0.1)^(1/12) -> 0.008741611
A8: Step -2
A9: Monthly Mortage Payment | B9: PMT - Interest + Scheduled Principal = Monthly Payment
B10: =PMT(6.44/100/12,334,-B2) -> 2912.6829 | D10: 2912.6829
A12: Step - 3
A13: Calculate month 1 interest | B13: Beginning UPB * Annual Interest rate /12
B14: =B2 * 6.44/100/12 -> 2425.2484 | D14: =D2*6.44/100/12 -> 2401.4548
A16: Step - 4
A17: Scheduled Principal | B17: Scheduled Principal = Monthly Payment - interest
B18: =B10-B14 -> 487.43447 | D18: =D10-D14 -> 511.22808
A20: Step - 5
A21: Balance Before Prepayment | B21: Beginning UPB -Scheduled Principal
B22: =B2-B18 -> 451422.21 | D22: =D2-D18 -> 446964.82
A24: Step - 6
A25: Month 1 prepayment | B25: Balance before prepayment * SMM
B26: =B22*0.008741611 -> 3946.1573 | D26: =D22*0.008741611 -> 3907.1926
A28: Step - 7
A29: Calculate Ending UPB | B29: Beginning UPB - Scheduled Principal - prepayment
B30: =B2-B18-B26 -> 447476.05 | D30: =D2-D18-D26 -> 443057.63
A32: Step - 8
A33: Calculate Servicing Revenue | B33: Beginning UPB * Annual Servicing rate/ 12
B34: =B2*0.0025/12 -> 94.147842 | D34: =D2*0.0025/12 -> 93.224177
A36: Step - 9
A37: Monthly Servicing Cost | B37: Annual Servicing Cost/12
B38: =60/12 -> 5 | D38: 5
A40: Step - 10 | B40: Monthly Anciallary Revenue
B41: 2 | D41: 2
A43: Step - 11
A44: Net MSR Cash Flow | B44: Servicing Revenue + Anciallary Revenue - Servicing Cost
B45: =B34+B41-B38 -> 91.147842 | D45: =D34+D41-D38 -> 90.224177
A47: Step - 12
A48: Monthly Discount rate | B48: (1+Annual Discount rate)^(1/12/)-1
B49: =(1+0.08)^(1/12)-1 -> 0.0064340301 | D49: =(1+0.08)^(1/12)-1 -> 0.0064340301
A51: Step - 13
A52: Present Value of Month 1 Cash Flow | B52: Formula (discounted cash flow (DCF))
B53: PV = Net MSR Cash Flow /(1+Monthly Discount rate)^Month
...

Sheet MSR Cash Flow
A1: Month | B1: Beginning_UPB | C1: Monthly_Payment | D1: Interest | E1: Scheduled_Principal | F1: Balance_Before_Prepayment | G1: Prepayment | H1: Ending_UPB | I1: Servicing_Revenue | J1: Servicing_Cost | K1: Ancillary_Revenue | L1: Net_MSR_Cash_Flow | M1: Monthly_Discount_Rate | N1: Present_Value | P1: LN000001 MSR Valuation Summary
A2: 1 | B2: =Loans!D2 -> 451909.64 | C2: =PMT(Loans!E2/100/12,Loans!H2,-Loans!D2) -> 2912.6829 | D2: =B2*(Loans!$E$2/100)/12 -> 2425.2484 | E2: =C2-D2 -> 487.43447 | F2: =B2-E2 -> 451422.21 | G2: =F2*Assumptions!$E$2 -> 3946.1573 | H2: =F2-G2 -> 447476.05 | I2: =B2*Loans!O2/12 -> 94.147842 | J2: =Assumptions!$B$5/12 -> 5 | K2: =Assumptions!$B$6 -> 2 | L2: =I2+K2-J2 -> 91.147842 | M2: =(1+Assumptions!$B$4)^(1/12)-1 -> 0.0064340301 | N2: =L2/(1+M2)^1 -> 90.565143
A3: 2 | B3: =H2 -> 447476.05 | C3: =IF(B3<=0,0,MIN($C$2,B3+D3)) -> 2912.6829 | D3: =IF(B3<=0,0,B3*(Loans!$E$2/100)/12) -> 2401.4548 | E3: =IF(B3<=0,0,MIN(C3-D3,B3)) -> 511.22808 | F3: =MAX(0,B3-E3) -> 446964.82 | G3: =IF(F3<=0,0,MIN(F3,F3*Assumptions!$E$2)) -> 3907.1926 | H3: =MAX(0,F3-G3) -> 443057.63 | I3: =IF(B3<=0,0,B3*Loans!$O$2/12) -> 93.224177 | J3: =IF(B3<=0,0,Assumptions!$B$5/12) -> 5 | K3: =IF(B3<=0,0,Assumptions!$B$6) -> 2 | L3: =I3+K3-J3 -> 90.224177 | M3: =(1+Assumptions!$B$4)^(1/12)-1 -> 0.0064340301 | N3: =IF(L3=0,0,L3/(1+M3)^A3) -> 89.074276 | P3: Loan ID | Q3: =Loans!A2 -> LN000001
A4: 3 | B4: =H3 -> 443057.63 | C4: =IF(B4<=0,0,MIN($C$2,B4+D4)) -> 2912.6829 | D4: =IF(B4<=0,0,B4*(Loans!$E$2/100)/12) -> 2377.7426 | E4: =IF(B4<=0,0,MIN(C4-D4,B4)) -> 534.94027 | F4: =MAX(0,B4-E4) -> 442522.69 | G4: =IF(F4<=0,0,MIN(F4,F4*Assumptions!$E$2)) -> 3868.3612 | H4: =MAX(0,F4-G4) -> 438654.33 | I4: =IF(B4<=0,0,B4*Loans!$O$2/12) -> 92.303672 | J4: =IF(B4<=0,0,Assumptions!$B$5/12) -> 5 | K4: =IF(B4<=0,0,Assumptions!$B$6) -> 2 | L4: =I4+K4-J4 -> 89.303672 | M4: =(1+Assumptions!$B$4)^(1/12)-1 -> 0.0064340301 | N4: =IF(L4=0,0,L4/(1+M4)^A4) -> 87.601871 | P4: Current UPD | Q4: =Loans!D2 -> 451909.64
A5: 4 | B5: =H4 -> 438654.33 | C5: =IF(B5<=0,0,MIN($C$2,B5+D5)) -> 2912.6829 | D5: =IF(B5<=0,0,B5*(Loans!$E$2/100)/12) -> 2354.1116 | E5: =IF(B5<=0,0,MIN(C5-D5,B5)) -> 558.57132 | F5: =MAX(0,B5-E5) -> 438095.75 | G5: =IF(F5<=0,0,MIN(F5,F5*Assumptions!$E$2)) -> 3829.6626 | H5: =MAX(0,F5-G5) -> 434266.09 | I5: =IF(B5<=0,0,B5*Loans!$O$2/12) -> 91.386318 | J5: =IF(B5<=0,0,Assumptions!$B$5/12) -> 5 | K5: =IF(B5<=0,0,Assumptions!$B$6) -> 2 | L5: =I5+K5-J5 -> 88.386318 | M5: =(1+Assumptions!$B$4)^(1/12)-1 -> 0.0064340301 | N5: =IF(L5=0,0,L5/(1+M5)^A5) -> 86.14772 | P5: Total MSR Value | Q5: =SUM(Table1[Present_Value]) -> 4059.9014
A6: 5 | B6: =H5 -> 434266.09 | C6: =IF(B6<=0,0,MIN($C$2,B6+D6)) -> 2912.6829 | D6: =IF(B6<=0,0,B6*(Loans!$E$2/100)/12) -> 2330.5614 | E6: =IF(B6<=0,0,MIN(C6-D6,B6)) -> 582.12151 | F6: =MAX(0,B6-E6) -> 433683.97 | G6: =IF(F6<=0,0,MIN(F6,F6*Assumptions!$E$2)) -> 3791.0965 | H6: =MAX(0,F6-G6) -> 429892.87 | I6: =IF(B6<=0,0,B6*Loans!$O$2/12) -> 90.472103 | J6: =IF(B6<=0,0,Assumptions!$B$5/12) -> 5 | K6: =IF(B6<=0,0,Assumptions!$B$6) -> 2 | L6: =I6+K6-J6 -> 87.472103 | M6: =(1+Assumptions!$B$4)^(1/12)-1 -> 0.0064340301 | N6: =IF(L6=0,0,L6/(1+M6)^A6) -> 84.711623 | P6: MSR Value % of UPB | Q6: =Q5/Q4 -> 0.0089838787
A7: 6 | B7: =H6 -> 429892.87 | C7: =IF(B7<=0,0,MIN($C$2,B7+D7)) -> 2912.6829 | D7: =IF(B7<=0,0,B7*(Loans!$E$2/100)/12) -> 2307.0918 | E7: =IF(B7<=0,0,MIN(C7-D7,B7)) -> 605.59112 | F7: =MAX(0,B7-E7) -> 429287.28 | G7: =IF(F7<=0,0,MIN(F7,F7*Assumptions!$E$2)) -> 3752.6624 | H7: =MAX(0,F7-G7) -> 425534.62 | I7: =IF(B7<=0,0,B7*Loans!$O$2/12) -> 89.561015 | J7: =IF(B7<=0,0,Assumptions!$B$5/12) -> 5 | K7: =IF(B7<=0,0,Assumptions!$B$6) -> 2 | L7: =I7+K7-J7 -> 86.561015 | M7: =(1+Assumptions!$B$4)^(1/12)-1 -> 0.0064340301 | N7: =IF(L7=0,0,L7/(1+M7)^A7) -> 83.293376 | P7: MSR Value basis points(bps) | Q7: =Q6*10000 -> 89.838787
A8: 7 | B8: =H7 -> 425534.62 | C8: =IF(B8<=0,0,MIN($C$2,B8+D8)) -> 2912.6829 | D8: =IF(B8<=0,0,B8*(Loans!$E$2/100)/12) -> 2283.7025 | E8: =IF(B8<=0,0,MIN(C8-D8,B8)) -> 628.98041 | F8: =MAX(0,B8-E8) -> 424905.64 | G8: =IF(F8<=0,0,MIN(F8,F8*Assumptions!$E$2)) -> 3714.3598 | H8: =MAX(0,F8-G8) -> 421191.28 | I8: =IF(B8<=0,0,B8*Loans!$O$2/12) -> 88.653046 | J8: =IF(B8<=0,0,Assumptions!$B$5/12) -> 5 | K8: =IF(B8<=0,0,Assumptions!$B$6) -> 2 | L8: =I8+K8-J8 -> 85.653046 | M8: =(1+Assumptions!$B$4)^(1/12)-1 -> 0.0064340301 | N8: =IF(L8=0,0,L8/(1+M8)^A8) -> 81.892781 | P8: Servicing multiple in bps | Q8: =Q6/Loans!O2 -> 3.5935515 | R8: MSR Value % of UPB/Servicing fee rate
A9: 8 | B9: =H8 -> 421191.28 | C9: =IF(B9<=0,0,MIN($C$2,B9+D9)) -> 2912.6829 | D9: =IF(B9<=0,0,B9*(Loans!$E$2/100)/12) -> 2260.3932 | E9: =IF(B9<=0,0,MIN(C9-D9,B9)) -> 652.28967 | F9: =MAX(0,B9-E9) -> 420538.99 | G9: =IF(F9<=0,0,MIN(F9,F9*Assumptions!$E$2)) -> 3676.1882 | H9: =MAX(0,F9-G9) -> 416862.8 | I9: =IF(B9<=0,0,B9*Loans!$O$2/12) -> 87.748183 | J9: =IF(B9<=0,0,Assumptions!$B$5/12) -> 5 | K9: =IF(B9<=0,0,Assumptions!$B$6) -> 2 | L9: =I9+K9-J9 -> 84.748183 | M9: =(1+Assumptions!$B$4)^(1/12)-1 -> 0.0064340301 | N9: =IF(L9=0,0,L9/(1+M9)^A9) -> 80.509642
A10: 9 | B10: =H9 -> 416862.8 | C10: =IF(B10<=0,0,MIN($C$2,B10+D10)) -> 2912.6829 | D10: =IF(B10<=0,0,B10*(Loans!$E$2/100)/12) -> 2237.1637 | E10: =IF(B10<=0,0,MIN(C10-D10,B10)) -> 675.51917 | F10: =MAX(0,B10-E10) -> 416187.28 | G10: =IF(F10<=0,0,MIN(F10,F10*Assumptions!$E$2)) -> 3638.1473 | H10: =MAX(0,F10-G10) -> 412549.14 | I10: =IF(B10<=0,0,B10*Loans!$O$2/12) -> 86.846417 | J10: =IF(B10<=0,0,Assumptions!$B$5/12) -> 5 | K10: =IF(B10<=0,0,Assumptions!$B$6) -> 2 | L10: =I10+K10-J10 -> 83.846417 | M10: =(1+Assumptions!$B$4)^(1/12)-1 -> 0.0064340301 | N10: =IF(L10=0,0,L10/(1+M10)^A10) -> 79.143763 | R10: So a 3.59× servicing multiple means:
A11: 10 | B11: =H10 -> 412549.14 | C11: =IF(B11<=0,0,MIN($C$2,B11+D11)) -> 2912.6829 | D11: =IF(B11<=0,0,B11*(Loans!$E$2/100)/12) -> 2214.0137 | E11: =IF(B11<=0,0,MIN(C11-D11,B11)) -> 698.66918 | F11: =MAX(0,B11-E11) -> 411850.47 | G11: =IF(F11<=0,0,MIN(F11,F11*Assumptions!$E$2)) -> 3600.2366 | H11: =MAX(0,F11-G11) -> 408250.23 | I11: =IF(B11<=0,0,B11*Loans!$O$2/12) -> 85.947737 | J11: =IF(B11<=0,0,Assumptions!$B$5/12) -> 5 | K11: =IF(B11<=0,0,Assumptions!$B$6) -> 2 | L11: =I11+K11-J11 -> 82.947737 | M11: =(1+Assumptions!$B$4)^(1/12)-1 -> 0.0064340301 | N11: =IF(L11=0,0,L11/(1+M11)^A11) -> 77.794951 | R11: The MSR is valued at approximately 3.59 times the annual contractual servicing fee.
A12: 11 | B12: =H11 -> 408250.23 | C12: =IF(B12<=0,0,MIN($C$2,B12+D12)) -> 2912.6829 | D12: =IF(B12<=0,0,B12*(Loans!$E$2/100)/12) -> 2190.9429 | E12: =IF(B12<=0,0,MIN(C12-D12,B12)) -> 721.73997 | F12: =MAX(0,B12-E12) -> 407528.49 | G12: =IF(F12<=0,0,MIN(F12,F12*Assumptions!$E$2)) -> 3562.4555 | H12: =MAX(0,F12-G12) -> 403966.03 | I12: =IF(B12<=0,0,B12*Loans!$O$2/12) -> 85.052131 | J12: =IF(B12<=0,0,Assumptions!$B$5/12) -> 5 | K12: =IF(B12<=0,0,Assumptions!$B$6) -> 2 | L12: =I12+K12-J12 -> 82.052131 | M12: =(1+Assumptions!$B$4)^(1/12)-1 -> 0.0064340301 | N12: =IF(L12=0,0,L12/(1+M12)^A12) -> 76.463016
A13: 12 | B13: =H12 -> 403966.03 | C13: =IF(B13<=0,0,MIN($C$2,B13+D13)) -> 2912.6829 | D13: =IF(B13<=0,0,B13*(Loans!$E$2/100)/12) -> 2167.9511 | E13: =IF(B13<=0,0,MIN(C13-D13,B13)) -> 744.73182 | F13: =MAX(0,B13-E13) -> 403221.3 | G13: =IF(F13<=0,0,MIN(F13,F13*Assumptions!$E$2)) -> 3524.8038 | H13: =MAX(0,F13-G13) -> 399696.5 | I13: =IF(B13<=0,0,B13*Loans!$O$2/12) -> 84.159591 | J13: =IF(B13<=0,0,Assumptions!$B$5/12) -> 5 | K13: =IF(B13<=0,0,Assumptions!$B$6) -> 2 | L13: =I13+K13-J13 -> 81.159591 | M13: =(1+Assumptions!$B$4)^(1/12)-1 -> 0.0064340301 | N13: =IF(L13=0,0,L13/(1+M13)^A13) -> 75.147769
A14: 13 | B14: =H13 -> 399696.5 | C14: =IF(B14<=0,0,MIN($C$2,B14+D14)) -> 2912.6829 | D14: =IF(B14<=0,0,B14*(Loans!$E$2/100)/12) -> 2145.0379 | E14: =IF(B14<=0,0,MIN(C14-D14,B14)) -> 767.64499 | F14: =MAX(0,B14-E14) -> 398928.85 | G14: =IF(F14<=0,0,MIN(F14,F14*Assumptions!$E$2)) -> 3487.2808 | H14: =MAX(0,F14-G14) -> 395441.57 | I14: =IF(B14<=0,0,B14*Loans!$O$2/12) -> 83.270104 | J14: =IF(B14<=0,0,Assumptions!$B$5/12) -> 5 | K14: =IF(B14<=0,0,Assumptions!$B$6) -> 2 | L14: =I14+K14-J14 -> 80.270104 | M14: =(1+Assumptions!$B$4)^(1/12)-1 -> 0.0064340301 | N14: =IF(L14=0,0,L14/(1+M14)^A14) -> 73.849024
A15: 14 | B15: =H14 -> 395441.57 | C15: =IF(B15<=0,0,MIN($C$2,B15+D15)) -> 2912.6829 | D15: =IF(B15<=0,0,B15*(Loans!$E$2/100)/12) -> 2122.2031 | E15: =IF(B15<=0,0,MIN(C15-D15,B15)) -> 790.47976 | F15: =MAX(0,B15-E15) -> 394651.09 | G15: =IF(F15<=0,0,MIN(F15,F15*Assumptions!$E$2)) -> 3449.8863 | H15: =MAX(0,F15-G15) -> 391201.21 | I15: =IF(B15<=0,0,B15*Loans!$O$2/12) -> 82.383661 | J15: =IF(B15<=0,0,Assumptions!$B$5/12) -> 5 | K15: =IF(B15<=0,0,Assumptions!$B$6) -> 2 | L15: =I15+K15-J15 -> 79.383661 | M15: =(1+Assumptions!$B$4)^(1/12)-1 -> 0.0064340301 | N15: =IF(L15=0,0,L15/(1+M15)^A15) -> 72.566595
A16: 15 | B16: =H15 -> 391201.21 | C16: =IF(B16<=0,0,MIN($C$2,B16+D16)) -> 2912.6829 | D16: =IF(B16<=0,0,B16*(Loans!$E$2/100)/12) -> 2099.4465 | E16: =IF(B16<=0,0,MIN(C16-D16,B16)) -> 813.23639 | F16: =MAX(0,B16-E16) -> 390387.97 | G16: =IF(F16<=0,0,MIN(F16,F16*Assumptions!$E$2)) -> 3412.6198 | H16: =MAX(0,F16-G16) -> 386975.35 | I16: =IF(B16<=0,0,B16*Loans!$O$2/12) -> 81.500252 | J16: =IF(B16<=0,0,Assumptions!$B$5/12) -> 5 | K16: =IF(B16<=0,0,Assumptions!$B$6) -> 2 | L16: =I16+K16-J16 -> 78.500252 | M16: =(1+Assumptions!$B$4)^(1/12)-1 -> 0.0064340301 | N16: =IF(L16=0,0,L16/(1+M16)^A16) -> 71.300299
A17: 16 | B17: =H16 -> 386975.35 | C17: =IF(B17<=0,0,MIN($C$2,B17+D17)) -> 2912.6829 | D17: =IF(B17<=0,0,B17*(Loans!$E$2/100)/12) -> 2076.7677 | E17: =IF(B17<=0,0,MIN(C17-D17,B17)) -> 835.91516 | F17: =MAX(0,B17-E17) -> 386139.44 | G17: =IF(F17<=0,0,MIN(F17,F17*Assumptions!$E$2)) -> 3375.4807 | H17: =MAX(0,F17-G17) -> 382763.96 | I17: =IF(B17<=0,0,B17*Loans!$O$2/12) -> 80.619865 | J17: =IF(B17<=0,0,Assumptions!$B$5/12) -> 5 | K17: =IF(B17<=0,0,Assumptions!$B$6) -> 2 | L17: =I17+K17-J17 -> 77.619865 | M17: =(1+Assumptions!$B$4)^(1/12)-1 -> 0.0064340301 | N17: =IF(L17=0,0,L17/(1+M17)^A17) -> 70.049957
A18: 17 | B18: =H17 -> 382763.96 | C18: =IF(B18<=0,0,MIN($C$2,B18+D18)) -> 2912.6829 | D18: =IF(B18<=0,0,B18*(Loans!$E$2/100)/12) -> 2054.1666 | E18: =IF(B18<=0,0,MIN(C18-D18,B18)) -> 858.51631 | F18: =MAX(0,B18-E18) -> 381905.44 | G18: =IF(F18<=0,0,MIN(F18,F18*Assumptions!$E$2)) -> 3338.4688 | H18: =MAX(0,F18-G18) -> 378566.97 | I18: =IF(B18<=0,0,B18*Loans!$O$2/12) -> 79.742491 | J18: =IF(B18<=0,0,Assumptions!$B$5/12) -> 5 | K18: =IF(B18<=0,0,Assumptions!$B$6) -> 2 | L18: =I18+K18-J18 -> 76.742491 | M18: =(1+Assumptions!$B$4)^(1/12)-1 -> 0.0064340301 | N18: =IF(L18=0,0,L18/(1+M18)^A18) -> 68.815389
A19: 18 | B19: =H18 -> 378566.97 | C19: =IF(B19<=0,0,MIN($C$2,B19+D19)) -> 2912.6829 | D19: =IF(B19<=0,0,B19*(Loans!$E$2/100)/12) -> 2031.6427 | E19: =IF(B19<=0,0,MIN(C19-D19,B19)) -> 881.04013 | F19: =MAX(0,B19-E19) -> 377685.93 | G19: =IF(F19<=0,0,MIN(F19,F19*Assumptions!$E$2)) -> 3301.5835 | H19: =MAX(0,F19-G19) -> 374384.35 | I19: =IF(B19<=0,0,B19*Loans!$O$2/12) -> 78.868119 | J19: =IF(B19<=0,0,Assumptions!$B$5/12) -> 5 | K19: =IF(B19<=0,0,Assumptions!$B$6) -> 2 | L19: =I19+K19-J19 -> 75.868119 | M19: =(1+Assumptions!$B$4)^(1/12)-1 -> 0.0064340301 | N19: =IF(L19=0,0,L19/(1+M19)^A19) -> 67.596418
A20: 19 | B20: =H19 -> 374384.35 | C20: =IF(B20<=0,0,MIN($C$2,B20+D20)) -> 2912.6829 | D20: =IF(B20<=0,0,B20*(Loans!$E$2/100)/12) -> 2009.196 | E20: =IF(B20<=0,0,MIN(C20-D20,B20)) -> 903.48688 | F20: =MAX(0,B20-E20) -> 373480.86 | G20: =IF(F20<=0,0,MIN(F20,F20*Assumptions!$E$2)) -> 3264.8244 | H20: =MAX(0,F20-G20) -> 370216.04 | I20: =IF(B20<=0,0,B20*Loans!$O$2/12) -> 77.996739 | J20: =IF(B20<=0,0,Assumptions!$B$5/12) -> 5 | K20: =IF(B20<=0,0,Assumptions!$B$6) -> 2 | L20: =I20+K20-J20 -> 74.996739 | M20: =(1+Assumptions!$B$4)^(1/12)-1 -> 0.0064340301 | N20: =IF(L20=0,0,L20/(1+M20)^A20) -> 66.392869
A21: 20 | B21: =H20 -> 370216.04 | C21: =IF(B21<=0,0,MIN($C$2,B21+D21)) -> 2912.6829 | D21: =IF(B21<=0,0,B21*(Loans!$E$2/100)/12) -> 1986.8261 | E21: =IF(B21<=0,0,MIN(C21-D21,B21)) -> 925.85682 | F21: =MAX(0,B21-E21) -> 369290.18 | G21: =IF(F21<=0,0,MIN(F21,F21*Assumptions!$E$2)) -> 3228.1911 | H21: =MAX(0,F21-G21) -> 366061.99 | I21: =IF(B21<=0,0,B21*Loans!$O$2/12) -> 77.128341 | J21: =IF(B21<=0,0,Assumptions!$B$5/12) -> 5 | K21: =IF(B21<=0,0,Assumptions!$B$6) -> 2 | L21: =I21+K21-J21 -> 74.128341 | M21: =(1+Assumptions!$B$4)^(1/12)-1 -> 0.0064340301 | N21: =IF(L21=0,0,L21/(1+M21)^A21) -> 65.204568
A22: 21 | B22: =H21 -> 366061.99 | C22: =IF(B22<=0,0,MIN($C$2,B22+D22)) -> 2912.6829 | D22: =IF(B22<=0,0,B22*(Loans!$E$2/100)/12) -> 1964.5327 | E22: =IF(B22<=0,0,MIN(C22-D22,B22)) -> 948.15021 | F22: =MAX(0,B22-E22) -> 365113.84 | G22: =IF(F22<=0,0,MIN(F22,F22*Assumptions!$E$2)) -> 3191.6831 | H22: =MAX(0,F22-G22) -> 361922.15 | I22: =IF(B22<=0,0,B22*Loans!$O$2/12) -> 76.262914 | J22: =IF(B22<=0,0,Assumptions!$B$5/12) -> 5 | K22: =IF(B22<=0,0,Assumptions!$B$6) -> 2 | L22: =I22+K22-J22 -> 73.262914 | M22: =(1+Assumptions!$B$4)^(1/12)-1 -> 0.0064340301 | N22: =IF(L22=0,0,L22/(1+M22)^A22) -> 64.031344
A23: 22 | B23: =H22 -> 361922.15 | C23: =IF(B23<=0,0,MIN($C$2,B23+D23)) -> 2912.6829 | D23: =IF(B23<=0,0,B23*(Loans!$E$2/100)/12) -> 1942.3156 | E23: =IF(B23<=0,0,MIN(C23-D23,B23)) -> 970.36731 | F23: =MAX(0,B23-E23) -> 360951.79 | G23: =IF(F23<=0,0,MIN(F23,F23*Assumptions!$E$2)) -> 3155.3001 | H23: =MAX(0,F23-G23) -> 357796.49 | I23: =IF(B23<=0,0,B23*Loans!$O$2/12) -> 75.400449 | J23: =IF(B23<=0,0,Assumptions!$B$5/12) -> 5 | K23: =IF(B23<=0,0,Assumptions!$B$6) -> 2 | L23: =I23+K23-J23 -> 72.400449 | M23: =(1+Assumptions!$B$4)^(1/12)-1 -> 0.0064340301 | N23: =IF(L23=0,0,L23/(1+M23)^A23) -> 62.873027
... A335: 334 | B335: =H334 -> 0 | C335: =IF(B335<=0,0,MIN($C$2,B335+D335)) -> 0 | D335: =IF(B335<=0,0,B335*(Loans!$E$2/100)/12) -> 0 | E335: =IF(B335<=0,0,MIN(C335-D335,B335)) -> 0 | F335: =MAX(0,B335-E335) -> 0 | G335: =IF(F335<=0,0,MIN(F335,F335*Assumptions!$E$2)) -> 0 | H335: =MAX(0,F335-G335) -> 0 | I335: =IF(B335<=0,0,B335*Loans!$O$2/12) -> 0 | J335: =IF(B335<=0,0,Assumptions!$B$5/12) -> 0 | K335: =IF(B335<=0,0,Assumptions!$B$6) -> 0 | L335: =I335+K335-J335 -> 0 | M335: =(1+Assumptions!$B$4)^(1/12)-1 -> 0.0064340301 | N335: =IF(L335=0,0,L335/(1+M335)^A335) -> 0

Sheet Portfolio Valuation Sheet
A1: Loan_ID | B1: Current_UPB | C1: Interst_rate | D1: Servicing_Fee_Rate | E1: Remaining_Term | F1: Include_In_Valuation | G1: MSR_Value | H1: MSR_Value_Pct_UPB | I1: MSR_Value_bps | J1: Servicing_Multiple
A2: =Loans!A2 -> LN000001 | B2: =Loans!D2 -> 451909.64 | C2: =Loans!E2 -> 6.44 | D2: =Loans!O2 -> 0.0025 | E2: =Loans!H2 -> 334 | F2: =Loans!U2 -> YES
A3: =Loans!A3 -> LN000002 | B3: =Loans!D3 -> 380046.3 | C3: =Loans!E3 -> 6.214 | D3: =Loans!O3 -> 0.0025 | E3: =Loans!H3 -> 111 | F3: =Loans!U3 -> YES
A4: =Loans!A4 -> LN000003 | B4: =Loans!D4 -> 243727.48 | C4: =Loans!E4 -> 7.079 | D4: =Loans!O4 -> 0.0025 | E4: =Loans!H4 -> 318 | F4: =Loans!U4 -> YES
A5: =Loans!A5 -> LN000004 | B5: =Loans!D5 -> 422332.15 | C5: =Loans!E5 -> 6.764 | D5: =Loans!O5 -> 0.0025 | E5: =Loans!H5 -> 328 | F5: =Loans!U5 -> YES
A6: =Loans!A6 -> LN000005 | B6: =Loans!D6 -> 303414.81 | C6: =Loans!E6 -> 6.763 | D6: =Loans!O6 -> 0.0025 | E6: =Loans!H6 -> 120 | F6: =Loans!U6 -> YES
A7: =Loans!A7 -> LN000006 | B7: =Loans!D7 -> 458369.93 | C7: =Loans!E7 -> 6.421 | D7: =Loans!O7 -> 0.00275 | E7: =Loans!H7 -> 146 | F7: =Loans!U7 -> YES
A8: =Loans!A8 -> LN000007 | B8: =Loans!D8 -> 569933.7 | C8: =Loans!E8 -> 5.625 | D8: =Loans!O8 -> 0.0025 | E8: =Loans!H8 -> 335 | F8: =Loans!U8 -> YES
A9: =Loans!A9 -> LN000008 | B9: =Loans!D9 -> 144019.89 | C9: =Loans!E9 -> 6.461 | D9: =Loans!O9 -> 0.0025 | E9: =Loans!H9 -> 330 | F9: =Loans!U9 -> YES
A10: =Loans!A10 -> LN000009 | B10: =Loans!D10 -> 405607.96 | C10: =Loans!E10 -> 6.292 | D10: =Loans!O10 -> 0.0025 | E10: =Loans!H10 -> 292 | F10: =Loans!U10 -> YES
A11: =Loans!A11 -> LN000010 | B11: =Loans!D11 -> 158337.27 | C11: =Loans!E11 -> 5.51 | D11: =Loans!O11 -> 0.0025 | E11: =Loans!H11 -> 319 | F11: =Loans!U11 -> YES
A12: =Loans!A12 -> LN000011 | B12: =Loans!D12 -> 417585.58 | C12: =Loans!E12 -> 7.036 | D12: =Loans!O12 -> 0.0025 | E12: =Loans!H12 -> 353 | F12: =Loans!U12 -> YES
A13: =Loans!A13 -> LN000012 | B13: =Loans!D13 -> 274812.8 | C13: =Loans!E13 -> 6.966 | D13: =Loans!O13 -> 0.0025 | E13: =Loans!H13 -> 333 | F13: =Loans!U13 -> YES
... A1001: =Loans!A1001 -> LN001000 | B1001: =Loans!D1001 -> 196448.22 | C1001: =Loans!E1001 -> 7.13 | D1001: =Loans!O1001 -> 0.00275 | E1001: =Loans!H1001 -> 309 | F1001: =Loans!U1001 -> YES
